404 Not Found: The requested URL was not found on the server. If you entered the URL manually please check your spelling and try again.
404 Not Found: The requested URL was not found on the server. If you entered the URL manually please check your spelling and try again.
404 Not Found: The requested URL was not found on the server. If you entered the URL manually please check your spelling and try again.
404 Not Found: The requested URL was not found on the server. If you entered the URL manually please check your spelling and try again.
Exception on / [GET]
Traceback (most recent call last):
  File "D:\python\Python38\lib\site-packages\flask\app.py", line 2447, in wsgi_app
    response = self.full_dispatch_request()
  File "D:\python\Python38\lib\site-packages\flask\app.py", line 1952, in full_dispatch_request
    rv = self.handle_user_exception(e)
  File "D:\python\Python38\lib\site-packages\flask\app.py", line 1821, in handle_user_exception
    reraise(exc_type, exc_value, tb)
  File "D:\python\Python38\lib\site-packages\flask\_compat.py", line 39, in reraise
    raise value
  File "D:\python\Python38\lib\site-packages\flask\app.py", line 1950, in full_dispatch_request
    rv = self.dispatch_request()
  File "D:\python\Python38\lib\site-packages\flask\app.py", line 1936, in dispatch_request
    return self.view_functions[rule.endpoint](**req.view_args)
  File "app.py", line 46, in home_html
    return render_template("english_bot1.html")
  File "D:\python\Python38\lib\site-packages\flask\templating.py", line 138, in render_template
    ctx.app.jinja_env.get_or_select_template(template_name_or_list),
  File "D:\python\Python38\lib\site-packages\jinja2\environment.py", line 930, in get_or_select_template
    return self.get_template(template_name_or_list, parent, globals)
  File "D:\python\Python38\lib\site-packages\jinja2\environment.py", line 883, in get_template
    return self._load_template(name, self.make_globals(globals))
  File "D:\python\Python38\lib\site-packages\jinja2\environment.py", line 857, in _load_template
    template = self.loader.load(self, name, globals)
  File "D:\python\Python38\lib\site-packages\jinja2\loaders.py", line 115, in load
    source, filename, uptodate = self.get_source(environment, name)
  File "D:\python\Python38\lib\site-packages\flask\templating.py", line 60, in get_source
    return self._get_source_fast(environment, template)
  File "D:\python\Python38\lib\site-packages\flask\templating.py", line 89, in _get_source_fast
    raise TemplateNotFound(template)
jinja2.exceptions.TemplateNotFound: english_bot1.html
500 Internal Server Error: The server encountered an internal error and was unable to complete your request. Either the server is overloaded or there is an error in the application.
404 Not Found: The requested URL was not found on the server. If you entered the URL manually please check your spelling and try again.
404 Not Found: The requested URL was not found on the server. If you entered the URL manually please check your spelling and try again.
404 Not Found: The requested URL was not found on the server. If you entered the URL manually please check your spelling and try again.
Exception on /api/get_sentence [GET]
Traceback (most recent call last):
  File "D:\python\Python38\lib\site-packages\flask\app.py", line 2447, in wsgi_app
    response = self.full_dispatch_request()
  File "D:\python\Python38\lib\site-packages\flask\app.py", line 1952, in full_dispatch_request
    rv = self.handle_user_exception(e)
  File "D:\python\Python38\lib\site-packages\flask\app.py", line 1821, in handle_user_exception
    reraise(exc_type, exc_value, tb)
  File "D:\python\Python38\lib\site-packages\flask\_compat.py", line 39, in reraise
    raise value
  File "D:\python\Python38\lib\site-packages\flask\app.py", line 1950, in full_dispatch_request
    rv = self.dispatch_request()
  File "D:\python\Python38\lib\site-packages\flask\app.py", line 1936, in dispatch_request
    return self.view_functions[rule.endpoint](**req.view_args)
  File "app.py", line 60, in word_present_sentence
    word_for_sentence = print_sentence(word_sentence)
  File "app.py", line 27, in print_sentence
    syns = wn.synsets(item)
  File "D:\python\Python38\lib\site-packages\nltk\corpus\util.py", line 99, in __getattr__
    self.__load()
  File "D:\python\Python38\lib\site-packages\nltk\corpus\util.py", line 73, in __load
    args, kwargs  = self.__args, self.__kwargs
AttributeError: 'WordNetCorpusReader' object has no attribute '_LazyCorpusLoader__args'
500 Internal Server Error: The server encountered an internal error and was unable to complete your request. Either the server is overloaded or there is an error in the application.
404 Not Found: The requested URL was not found on the server. If you entered the URL manually please check your spelling and try again.
404 Not Found: The requested URL was not found on the server. If you entered the URL manually please check your spelling and try again.
404 Not Found: The requested URL was not found on the server. If you entered the URL manually please check your spelling and try again.
Exception on /api/get_sentence [GET]
Traceback (most recent call last):
  File "D:\python\Python38\lib\site-packages\flask\app.py", line 2447, in wsgi_app
    response = self.full_dispatch_request()
  File "D:\python\Python38\lib\site-packages\flask\app.py", line 1952, in full_dispatch_request
    rv = self.handle_user_exception(e)
  File "D:\python\Python38\lib\site-packages\flask\app.py", line 1821, in handle_user_exception
    reraise(exc_type, exc_value, tb)
  File "D:\python\Python38\lib\site-packages\flask\_compat.py", line 39, in reraise
    raise value
  File "D:\python\Python38\lib\site-packages\flask\app.py", line 1950, in full_dispatch_request
    rv = self.dispatch_request()
  File "D:\python\Python38\lib\site-packages\flask\app.py", line 1936, in dispatch_request
    return self.view_functions[rule.endpoint](**req.view_args)
  File "app.py", line 63, in word_present_sentence
    word_for_sentence = print_sentence(word_sentence)
  File "app.py", line 31, in print_sentence
    for l in item.lemmas:
TypeError: 'method' object is not iterable
500 Internal Server Error: The server encountered an internal error and was unable to complete your request. Either the server is overloaded or there is an error in the application.
404 Not Found: The requested URL was not found on the server. If you entered the URL manually please check your spelling and try again.
404 Not Found: The requested URL was not found on the server. If you entered the URL manually please check your spelling and try again.
Exception on /api/get_sentence [GET]
Traceback (most recent call last):
  File "D:\python\Python38\lib\site-packages\flask\app.py", line 2447, in wsgi_app
    response = self.full_dispatch_request()
  File "D:\python\Python38\lib\site-packages\flask\app.py", line 1952, in full_dispatch_request
    rv = self.handle_user_exception(e)
  File "D:\python\Python38\lib\site-packages\flask\app.py", line 1821, in handle_user_exception
    reraise(exc_type, exc_value, tb)
  File "D:\python\Python38\lib\site-packages\flask\_compat.py", line 39, in reraise
    raise value
  File "D:\python\Python38\lib\site-packages\flask\app.py", line 1950, in full_dispatch_request
    rv = self.dispatch_request()
  File "D:\python\Python38\lib\site-packages\flask\app.py", line 1936, in dispatch_request
    return self.view_functions[rule.endpoint](**req.view_args)
  File "app.py", line 63, in word_present_sentence
    word_for_sentence = print_sentence(word_sentence)
  File "app.py", line 31, in print_sentence
    for l in item.lemmas:
TypeError: 'method' object is not iterable
500 Internal Server Error: The server encountered an internal error and was unable to complete your request. Either the server is overloaded or there is an error in the application.
404 Not Found: The requested URL was not found on the server. If you entered the URL manually please check your spelling and try again.
404 Not Found: The requested URL was not found on the server. If you entered the URL manually please check your spelling and try again.
Exception on /api/get_sentence [GET]
Traceback (most recent call last):
  File "D:\python\Python38\lib\site-packages\flask\app.py", line 2447, in wsgi_app
    response = self.full_dispatch_request()
  File "D:\python\Python38\lib\site-packages\flask\app.py", line 1952, in full_dispatch_request
    rv = self.handle_user_exception(e)
  File "D:\python\Python38\lib\site-packages\flask\app.py", line 1821, in handle_user_exception
    reraise(exc_type, exc_value, tb)
  File "D:\python\Python38\lib\site-packages\flask\_compat.py", line 39, in reraise
    raise value
  File "D:\python\Python38\lib\site-packages\flask\app.py", line 1950, in full_dispatch_request
    rv = self.dispatch_request()
  File "D:\python\Python38\lib\site-packages\flask\app.py", line 1936, in dispatch_request
    return self.view_functions[rule.endpoint](**req.view_args)
  File "app.py", line 63, in word_present_sentence
    return jsonify(word_for_sentence)
  File "D:\python\Python38\lib\site-packages\flask\json\__init__.py", line 370, in jsonify
    dumps(data, indent=indent, separators=separators) + "\n",
  File "D:\python\Python38\lib\site-packages\flask\json\__init__.py", line 211, in dumps
    rv = _json.dumps(obj, **kwargs)
  File "D:\python\Python38\lib\json\__init__.py", line 234, in dumps
    return cls(
  File "D:\python\Python38\lib\json\encoder.py", line 199, in encode
    chunks = self.iterencode(o, _one_shot=True)
  File "D:\python\Python38\lib\json\encoder.py", line 257, in iterencode
    return _iterencode(o, 0)
  File "D:\python\Python38\lib\site-packages\flask\json\__init__.py", line 100, in default
    return _json.JSONEncoder.default(self, o)
  File "D:\python\Python38\lib\json\encoder.py", line 179, in default
    raise TypeError(f'Object of type {o.__class__.__name__} '
TypeError: Object of type method is not JSON serializable
500 Internal Server Error: The server encountered an internal error and was unable to complete your request. Either the server is overloaded or there is an error in the application.
404 Not Found: The requested URL was not found on the server. If you entered the URL manually please check your spelling and try again.
404 Not Found: The requested URL was not found on the server. If you entered the URL manually please check your spelling and try again.
404 Not Found: The requested URL was not found on the server. If you entered the URL manually please check your spelling and try again.
404 Not Found: The requested URL was not found on the server. If you entered the URL manually please check your spelling and try again.
Exception on /api/get_sentence [GET]
Traceback (most recent call last):
  File "D:\python\Python38\lib\site-packages\flask\app.py", line 2447, in wsgi_app
    response = self.full_dispatch_request()
  File "D:\python\Python38\lib\site-packages\flask\app.py", line 1952, in full_dispatch_request
    rv = self.handle_user_exception(e)
  File "D:\python\Python38\lib\site-packages\flask\app.py", line 1821, in handle_user_exception
    reraise(exc_type, exc_value, tb)
  File "D:\python\Python38\lib\site-packages\flask\_compat.py", line 39, in reraise
    raise value
  File "D:\python\Python38\lib\site-packages\flask\app.py", line 1950, in full_dispatch_request
    rv = self.dispatch_request()
  File "D:\python\Python38\lib\site-packages\flask\app.py", line 1936, in dispatch_request
    return self.view_functions[rule.endpoint](**req.view_args)
  File "app.py", line 57, in word_present_sentence
    word_for_sentence = print_sentence(word_sentence)
  File "app.py", line 27, in print_sentence
    print(wordnet.synsets(item).examples())
AttributeError: 'list' object has no attribute 'examples'
500 Internal Server Error: The server encountered an internal error and was unable to complete your request. Either the server is overloaded or there is an error in the application.
404 Not Found: The requested URL was not found on the server. If you entered the URL manually please check your spelling and try again.
404 Not Found: The requested URL was not found on the server. If you entered the URL manually please check your spelling and try again.
Exception on /api/get_sentence [GET]
Traceback (most recent call last):
  File "D:\python\Python38\lib\site-packages\flask\app.py", line 2447, in wsgi_app
    response = self.full_dispatch_request()
  File "D:\python\Python38\lib\site-packages\flask\app.py", line 1952, in full_dispatch_request
    rv = self.handle_user_exception(e)
  File "D:\python\Python38\lib\site-packages\flask\app.py", line 1821, in handle_user_exception
    reraise(exc_type, exc_value, tb)
  File "D:\python\Python38\lib\site-packages\flask\_compat.py", line 39, in reraise
    raise value
  File "D:\python\Python38\lib\site-packages\flask\app.py", line 1950, in full_dispatch_request
    rv = self.dispatch_request()
  File "D:\python\Python38\lib\site-packages\flask\app.py", line 1936, in dispatch_request
    return self.view_functions[rule.endpoint](**req.view_args)
  File "app.py", line 59, in word_present_sentence
    word_for_sentence = print_sentence(word_sentence)
  File "app.py", line 29, in print_sentence
    print(wn.synsets(item)[0].examples())
  File "D:\python\Python38\lib\site-packages\nltk\corpus\reader\wordnet.py", line 1416, in synsets
    lemma = lemma.lower()
AttributeError: 'Synset' object has no attribute 'lower'
500 Internal Server Error: The server encountered an internal error and was unable to complete your request. Either the server is overloaded or there is an error in the application.
404 Not Found: The requested URL was not found on the server. If you entered the URL manually please check your spelling and try again.
Exception on /api/get_sentence [GET]
Traceback (most recent call last):
  File "D:\python\Python38\lib\site-packages\flask\app.py", line 2447, in wsgi_app
    response = self.full_dispatch_request()
  File "D:\python\Python38\lib\site-packages\flask\app.py", line 1952, in full_dispatch_request
    rv = self.handle_user_exception(e)
  File "D:\python\Python38\lib\site-packages\flask\app.py", line 1821, in handle_user_exception
    reraise(exc_type, exc_value, tb)
  File "D:\python\Python38\lib\site-packages\flask\_compat.py", line 39, in reraise
    raise value
  File "D:\python\Python38\lib\site-packages\flask\app.py", line 1950, in full_dispatch_request
    rv = self.dispatch_request()
  File "D:\python\Python38\lib\site-packages\flask\app.py", line 1936, in dispatch_request
    return self.view_functions[rule.endpoint](**req.view_args)
  File "app.py", line 59, in word_present_sentence
    word_for_sentence = print_sentence(word_sentence)
  File "app.py", line 29, in print_sentence
    print(wn.synsets(item.casefold())[0].examples())
AttributeError: 'Synset' object has no attribute 'casefold'
500 Internal Server Error: The server encountered an internal error and was unable to complete your request. Either the server is overloaded or there is an error in the application.
404 Not Found: The requested URL was not found on the server. If you entered the URL manually please check your spelling and try again.
Exception on /api/get_sentence [GET]
Traceback (most recent call last):
  File "D:\python\Python38\lib\site-packages\flask\app.py", line 2447, in wsgi_app
    response = self.full_dispatch_request()
  File "D:\python\Python38\lib\site-packages\flask\app.py", line 1952, in full_dispatch_request
    rv = self.handle_user_exception(e)
  File "D:\python\Python38\lib\site-packages\flask\app.py", line 1821, in handle_user_exception
    reraise(exc_type, exc_value, tb)
  File "D:\python\Python38\lib\site-packages\flask\_compat.py", line 39, in reraise
    raise value
  File "D:\python\Python38\lib\site-packages\flask\app.py", line 1950, in full_dispatch_request
    rv = self.dispatch_request()
  File "D:\python\Python38\lib\site-packages\flask\app.py", line 1936, in dispatch_request
    return self.view_functions[rule.endpoint](**req.view_args)
  File "app.py", line 59, in word_present_sentence
    word_for_sentence = print_sentence(word_sentence)
  File "app.py", line 29, in print_sentence
    print(wn.synsets(item)[0].examples())
  File "D:\python\Python38\lib\site-packages\nltk\corpus\reader\wordnet.py", line 1416, in synsets
    lemma = lemma.lower()
AttributeError: 'Synset' object has no attribute 'lower'
500 Internal Server Error: The server encountered an internal error and was unable to complete your request. Either the server is overloaded or there is an error in the application.
404 Not Found: The requested URL was not found on the server. If you entered the URL manually please check your spelling and try again.
Exception on /api/get_sentence [GET]
Traceback (most recent call last):
  File "D:\python\Python38\lib\site-packages\flask\app.py", line 2447, in wsgi_app
    response = self.full_dispatch_request()
  File "D:\python\Python38\lib\site-packages\flask\app.py", line 1952, in full_dispatch_request
    rv = self.handle_user_exception(e)
  File "D:\python\Python38\lib\site-packages\flask\app.py", line 1821, in handle_user_exception
    reraise(exc_type, exc_value, tb)
  File "D:\python\Python38\lib\site-packages\flask\_compat.py", line 39, in reraise
    raise value
  File "D:\python\Python38\lib\site-packages\flask\app.py", line 1950, in full_dispatch_request
    rv = self.dispatch_request()
  File "D:\python\Python38\lib\site-packages\flask\app.py", line 1936, in dispatch_request
    return self.view_functions[rule.endpoint](**req.view_args)
  File "app.py", line 57, in word_present_sentence
    word_for_sentence = print_sentence(word_sentence)
  File "app.py", line 26, in print_sentence
    if item in word_in_sentence:
NameError: name 'item' is not defined
500 Internal Server Error: The server encountered an internal error and was unable to complete your request. Either the server is overloaded or there is an error in the application.
404 Not Found: The requested URL was not found on the server. If you entered the URL manually please check your spelling and try again.
Exception on /api/get_sentence [GET]
Traceback (most recent call last):
  File "D:\python\Python38\lib\site-packages\flask\app.py", line 2447, in wsgi_app
    response = self.full_dispatch_request()
  File "D:\python\Python38\lib\site-packages\flask\app.py", line 1952, in full_dispatch_request
    rv = self.handle_user_exception(e)
  File "D:\python\Python38\lib\site-packages\flask\app.py", line 1821, in handle_user_exception
    reraise(exc_type, exc_value, tb)
  File "D:\python\Python38\lib\site-packages\flask\_compat.py", line 39, in reraise
    raise value
  File "D:\python\Python38\lib\site-packages\flask\app.py", line 1950, in full_dispatch_request
    rv = self.dispatch_request()
  File "D:\python\Python38\lib\site-packages\flask\app.py", line 1936, in dispatch_request
    return self.view_functions[rule.endpoint](**req.view_args)
  File "app.py", line 58, in word_present_sentence
    word_for_sentence = print_sentence(word_sentence)
  File "app.py", line 27, in print_sentence
    if item in items:
NameError: name 'item' is not defined
500 Internal Server Error: The server encountered an internal error and was unable to complete your request. Either the server is overloaded or there is an error in the application.
404 Not Found: The requested URL was not found on the server. If you entered the URL manually please check your spelling and try again.
404 Not Found: The requested URL was not found on the server. If you entered the URL manually please check your spelling and try again.
Exception on /api/get_sentence [GET]
Traceback (most recent call last):
  File "D:\python\Python38\lib\site-packages\flask\app.py", line 2447, in wsgi_app
    response = self.full_dispatch_request()
  File "D:\python\Python38\lib\site-packages\flask\app.py", line 1952, in full_dispatch_request
    rv = self.handle_user_exception(e)
  File "D:\python\Python38\lib\site-packages\flask\app.py", line 1821, in handle_user_exception
    reraise(exc_type, exc_value, tb)
  File "D:\python\Python38\lib\site-packages\flask\_compat.py", line 39, in reraise
    raise value
  File "D:\python\Python38\lib\site-packages\flask\app.py", line 1950, in full_dispatch_request
    rv = self.dispatch_request()
  File "D:\python\Python38\lib\site-packages\flask\app.py", line 1936, in dispatch_request
    return self.view_functions[rule.endpoint](**req.view_args)
  File "app.py", line 58, in word_present_sentence
    word_for_sentence = print_sentence(word_sentence)
  File "app.py", line 28, in print_sentence
    print(wn.synsets(item)[0].examples())
IndexError: list index out of range
500 Internal Server Error: The server encountered an internal error and was unable to complete your request. Either the server is overloaded or there is an error in the application.
404 Not Found: The requested URL was not found on the server. If you entered the URL manually please check your spelling and try again.
Exception on /api/get_sentence [GET]
Traceback (most recent call last):
  File "D:\python\Python38\lib\site-packages\flask\app.py", line 2447, in wsgi_app
    response = self.full_dispatch_request()
  File "D:\python\Python38\lib\site-packages\flask\app.py", line 1952, in full_dispatch_request
    rv = self.handle_user_exception(e)
  File "D:\python\Python38\lib\site-packages\flask\app.py", line 1821, in handle_user_exception
    reraise(exc_type, exc_value, tb)
  File "D:\python\Python38\lib\site-packages\flask\_compat.py", line 39, in reraise
    raise value
  File "D:\python\Python38\lib\site-packages\flask\app.py", line 1950, in full_dispatch_request
    rv = self.dispatch_request()
  File "D:\python\Python38\lib\site-packages\flask\app.py", line 1936, in dispatch_request
    return self.view_functions[rule.endpoint](**req.view_args)
  File "app.py", line 58, in word_present_sentence
    word_for_sentence = print_sentence(word_sentence)
  File "app.py", line 28, in print_sentence
    print(wn.synsets(word)[0].examples())
IndexError: list index out of range
500 Internal Server Error: The server encountered an internal error and was unable to complete your request. Either the server is overloaded or there is an error in the application.
Exception on /api/get_sentence [GET]
Traceback (most recent call last):
  File "D:\python\Python38\lib\site-packages\flask\app.py", line 2447, in wsgi_app
    response = self.full_dispatch_request()
  File "D:\python\Python38\lib\site-packages\flask\app.py", line 1952, in full_dispatch_request
    rv = self.handle_user_exception(e)
  File "D:\python\Python38\lib\site-packages\flask\app.py", line 1821, in handle_user_exception
    reraise(exc_type, exc_value, tb)
  File "D:\python\Python38\lib\site-packages\flask\_compat.py", line 39, in reraise
    raise value
  File "D:\python\Python38\lib\site-packages\flask\app.py", line 1950, in full_dispatch_request
    rv = self.dispatch_request()
  File "D:\python\Python38\lib\site-packages\flask\app.py", line 1936, in dispatch_request
    return self.view_functions[rule.endpoint](**req.view_args)
  File "app.py", line 58, in word_present_sentence
    word_for_sentence = print_sentence(word_sentence)
  File "app.py", line 28, in print_sentence
    print(wn.synsets(word)[0].examples())
IndexError: list index out of range
500 Internal Server Error: The server encountered an internal error and was unable to complete your request. Either the server is overloaded or there is an error in the application.
Exception on /api/get_sentence [GET]
Traceback (most recent call last):
  File "D:\python\Python38\lib\site-packages\flask\app.py", line 2447, in wsgi_app
    response = self.full_dispatch_request()
  File "D:\python\Python38\lib\site-packages\flask\app.py", line 1952, in full_dispatch_request
    rv = self.handle_user_exception(e)
  File "D:\python\Python38\lib\site-packages\flask\app.py", line 1821, in handle_user_exception
    reraise(exc_type, exc_value, tb)
  File "D:\python\Python38\lib\site-packages\flask\_compat.py", line 39, in reraise
    raise value
  File "D:\python\Python38\lib\site-packages\flask\app.py", line 1950, in full_dispatch_request
    rv = self.dispatch_request()
  File "D:\python\Python38\lib\site-packages\flask\app.py", line 1936, in dispatch_request
    return self.view_functions[rule.endpoint](**req.view_args)
  File "app.py", line 58, in word_present_sentence
    word_for_sentence = print_sentence(word_sentence)
  File "app.py", line 28, in print_sentence
    print(wn.synsets(word)[0].examples())
IndexError: list index out of range
500 Internal Server Error: The server encountered an internal error and was unable to complete your request. Either the server is overloaded or there is an error in the application.
404 Not Found: The requested URL was not found on the server. If you entered the URL manually please check your spelling and try again.
Exception on /api/get_sentence [GET]
Traceback (most recent call last):
  File "D:\python\Python38\lib\site-packages\flask\app.py", line 2447, in wsgi_app
    response = self.full_dispatch_request()
  File "D:\python\Python38\lib\site-packages\flask\app.py", line 1952, in full_dispatch_request
    rv = self.handle_user_exception(e)
  File "D:\python\Python38\lib\site-packages\flask\app.py", line 1821, in handle_user_exception
    reraise(exc_type, exc_value, tb)
  File "D:\python\Python38\lib\site-packages\flask\_compat.py", line 39, in reraise
    raise value
  File "D:\python\Python38\lib\site-packages\flask\app.py", line 1950, in full_dispatch_request
    rv = self.dispatch_request()
  File "D:\python\Python38\lib\site-packages\flask\app.py", line 1936, in dispatch_request
    return self.view_functions[rule.endpoint](**req.view_args)
  File "app.py", line 58, in word_present_sentence
    word_for_sentence = print_sentence(word_sentence)
  File "app.py", line 28, in print_sentence
    print(wn.synsets(word)[0].examples())
IndexError: list index out of range
500 Internal Server Error: The server encountered an internal error and was unable to complete your request. Either the server is overloaded or there is an error in the application.
Exception on /api/get_sentence [GET]
Traceback (most recent call last):
  File "D:\python\Python38\lib\site-packages\flask\app.py", line 2447, in wsgi_app
    response = self.full_dispatch_request()
  File "D:\python\Python38\lib\site-packages\flask\app.py", line 1952, in full_dispatch_request
    rv = self.handle_user_exception(e)
  File "D:\python\Python38\lib\site-packages\flask\app.py", line 1821, in handle_user_exception
    reraise(exc_type, exc_value, tb)
  File "D:\python\Python38\lib\site-packages\flask\_compat.py", line 39, in reraise
    raise value
  File "D:\python\Python38\lib\site-packages\flask\app.py", line 1950, in full_dispatch_request
    rv = self.dispatch_request()
  File "D:\python\Python38\lib\site-packages\flask\app.py", line 1936, in dispatch_request
    return self.view_functions[rule.endpoint](**req.view_args)
  File "app.py", line 58, in word_present_sentence
    word_for_sentence = print_sentence(word_sentence)
  File "app.py", line 28, in print_sentence
    print(wn.synsets(word)[0].examples())
IndexError: list index out of range
500 Internal Server Error: The server encountered an internal error and was unable to complete your request. Either the server is overloaded or there is an error in the application.
Exception on /api/get_sentence [GET]
Traceback (most recent call last):
  File "D:\python\Python38\lib\site-packages\flask\app.py", line 2447, in wsgi_app
    response = self.full_dispatch_request()
  File "D:\python\Python38\lib\site-packages\flask\app.py", line 1952, in full_dispatch_request
    rv = self.handle_user_exception(e)
  File "D:\python\Python38\lib\site-packages\flask\app.py", line 1821, in handle_user_exception
    reraise(exc_type, exc_value, tb)
  File "D:\python\Python38\lib\site-packages\flask\_compat.py", line 39, in reraise
    raise value
  File "D:\python\Python38\lib\site-packages\flask\app.py", line 1950, in full_dispatch_request
    rv = self.dispatch_request()
  File "D:\python\Python38\lib\site-packages\flask\app.py", line 1936, in dispatch_request
    return self.view_functions[rule.endpoint](**req.view_args)
  File "app.py", line 58, in word_present_sentence
    word_for_sentence = print_sentence(word_sentence)
  File "app.py", line 28, in print_sentence
    print(wn.synsets(word)[0].examples())
IndexError: list index out of range
500 Internal Server Error: The server encountered an internal error and was unable to complete your request. Either the server is overloaded or there is an error in the application.
404 Not Found: The requested URL was not found on the server. If you entered the URL manually please check your spelling and try again.
404 Not Found: The requested URL was not found on the server. If you entered the URL manually please check your spelling and try again.
404 Not Found: The requested URL was not found on the server. If you entered the URL manually please check your spelling and try again.
404 Not Found: The requested URL was not found on the server. If you entered the URL manually please check your spelling and try again.
404 Not Found: The requested URL was not found on the server. If you entered the URL manually please check your spelling and try again.
404 Not Found: The requested URL was not found on the server. If you entered the URL manually please check your spelling and try again.
404 Not Found: The requested URL was not found on the server. If you entered the URL manually please check your spelling and try again.
Exception on /api/get_sentence [GET]
Traceback (most recent call last):
  File "D:\python\Python38\lib\site-packages\flask\app.py", line 2447, in wsgi_app
    response = self.full_dispatch_request()
  File "D:\python\Python38\lib\site-packages\flask\app.py", line 1952, in full_dispatch_request
    rv = self.handle_user_exception(e)
  File "D:\python\Python38\lib\site-packages\flask\app.py", line 1821, in handle_user_exception
    reraise(exc_type, exc_value, tb)
  File "D:\python\Python38\lib\site-packages\flask\_compat.py", line 39, in reraise
    raise value
  File "D:\python\Python38\lib\site-packages\flask\app.py", line 1950, in full_dispatch_request
    rv = self.dispatch_request()
  File "D:\python\Python38\lib\site-packages\flask\app.py", line 1936, in dispatch_request
    return self.view_functions[rule.endpoint](**req.view_args)
  File "app.py", line 58, in word_present_sentence
    word_for_sentence = print_sentence(word_sentence)
  File "app.py", line 28, in print_sentence
    print(wn.synsets(word)[0].examples())
IndexError: list index out of range
500 Internal Server Error: The server encountered an internal error and was unable to complete your request. Either the server is overloaded or there is an error in the application.
Exception on /api/get_sentence [GET]
Traceback (most recent call last):
  File "D:\python\Python38\lib\site-packages\flask\app.py", line 2447, in wsgi_app
    response = self.full_dispatch_request()
  File "D:\python\Python38\lib\site-packages\flask\app.py", line 1952, in full_dispatch_request
    rv = self.handle_user_exception(e)
  File "D:\python\Python38\lib\site-packages\flask\app.py", line 1821, in handle_user_exception
    reraise(exc_type, exc_value, tb)
  File "D:\python\Python38\lib\site-packages\flask\_compat.py", line 39, in reraise
    raise value
  File "D:\python\Python38\lib\site-packages\flask\app.py", line 1950, in full_dispatch_request
    rv = self.dispatch_request()
  File "D:\python\Python38\lib\site-packages\flask\app.py", line 1936, in dispatch_request
    return self.view_functions[rule.endpoint](**req.view_args)
  File "app.py", line 58, in word_present_sentence
    word_for_sentence = print_sentence(word_sentence)
  File "app.py", line 28, in print_sentence
    print(wn.synsets(word)[0].examples())
IndexError: list index out of range
500 Internal Server Error: The server encountered an internal error and was unable to complete your request. Either the server is overloaded or there is an error in the application.
Exception on /api/get_sentence [GET]
Traceback (most recent call last):
  File "D:\python\Python38\lib\site-packages\flask\app.py", line 2447, in wsgi_app
    response = self.full_dispatch_request()
  File "D:\python\Python38\lib\site-packages\flask\app.py", line 1952, in full_dispatch_request
    rv = self.handle_user_exception(e)
  File "D:\python\Python38\lib\site-packages\flask\app.py", line 1821, in handle_user_exception
    reraise(exc_type, exc_value, tb)
  File "D:\python\Python38\lib\site-packages\flask\_compat.py", line 39, in reraise
    raise value
  File "D:\python\Python38\lib\site-packages\flask\app.py", line 1950, in full_dispatch_request
    rv = self.dispatch_request()
  File "D:\python\Python38\lib\site-packages\flask\app.py", line 1936, in dispatch_request
    return self.view_functions[rule.endpoint](**req.view_args)
  File "app.py", line 58, in word_present_sentence
    word_for_sentence = print_sentence(word_sentence)
  File "app.py", line 28, in print_sentence
    print(wn.synsets(word)[0].examples())
IndexError: list index out of range
500 Internal Server Error: The server encountered an internal error and was unable to complete your request. Either the server is overloaded or there is an error in the application.
Exception on /api/get_sentence [GET]
Traceback (most recent call last):
  File "D:\python\Python38\lib\site-packages\flask\app.py", line 2447, in wsgi_app
    response = self.full_dispatch_request()
  File "D:\python\Python38\lib\site-packages\flask\app.py", line 1952, in full_dispatch_request
    rv = self.handle_user_exception(e)
  File "D:\python\Python38\lib\site-packages\flask\app.py", line 1821, in handle_user_exception
    reraise(exc_type, exc_value, tb)
  File "D:\python\Python38\lib\site-packages\flask\_compat.py", line 39, in reraise
    raise value
  File "D:\python\Python38\lib\site-packages\flask\app.py", line 1950, in full_dispatch_request
    rv = self.dispatch_request()
  File "D:\python\Python38\lib\site-packages\flask\app.py", line 1936, in dispatch_request
    return self.view_functions[rule.endpoint](**req.view_args)
  File "app.py", line 58, in word_present_sentence
    word_for_sentence = print_sentence(word_sentence)
  File "app.py", line 28, in print_sentence
    print(wn.synsets(word)[0].examples())
IndexError: list index out of range
500 Internal Server Error: The server encountered an internal error and was unable to complete your request. Either the server is overloaded or there is an error in the application.
404 Not Found: The requested URL was not found on the server. If you entered the URL manually please check your spelling and try again.
Exception on /api/get_sentence [GET]
Traceback (most recent call last):
  File "D:\python\Python38\lib\site-packages\flask\app.py", line 2447, in wsgi_app
    response = self.full_dispatch_request()
  File "D:\python\Python38\lib\site-packages\flask\app.py", line 1952, in full_dispatch_request
    rv = self.handle_user_exception(e)
  File "D:\python\Python38\lib\site-packages\flask\app.py", line 1821, in handle_user_exception
    reraise(exc_type, exc_value, tb)
  File "D:\python\Python38\lib\site-packages\flask\_compat.py", line 39, in reraise
    raise value
  File "D:\python\Python38\lib\site-packages\flask\app.py", line 1950, in full_dispatch_request
    rv = self.dispatch_request()
  File "D:\python\Python38\lib\site-packages\flask\app.py", line 1936, in dispatch_request
    return self.view_functions[rule.endpoint](**req.view_args)
  File "app.py", line 58, in word_present_sentence
    word_for_sentence = print_sentence(word_sentence)
  File "app.py", line 28, in print_sentence
    print(wn.synsets(word)[0].examples())
IndexError: list index out of range
500 Internal Server Error: The server encountered an internal error and was unable to complete your request. Either the server is overloaded or there is an error in the application.
Exception on /api/get_sentence [GET]
Traceback (most recent call last):
  File "D:\python\Python38\lib\site-packages\flask\app.py", line 2447, in wsgi_app
    response = self.full_dispatch_request()
  File "D:\python\Python38\lib\site-packages\flask\app.py", line 1952, in full_dispatch_request
    rv = self.handle_user_exception(e)
  File "D:\python\Python38\lib\site-packages\flask\app.py", line 1821, in handle_user_exception
    reraise(exc_type, exc_value, tb)
  File "D:\python\Python38\lib\site-packages\flask\_compat.py", line 39, in reraise
    raise value
  File "D:\python\Python38\lib\site-packages\flask\app.py", line 1950, in full_dispatch_request
    rv = self.dispatch_request()
  File "D:\python\Python38\lib\site-packages\flask\app.py", line 1936, in dispatch_request
    return self.view_functions[rule.endpoint](**req.view_args)
  File "app.py", line 58, in word_present_sentence
    word_for_sentence = print_sentence(word_sentence)
  File "app.py", line 28, in print_sentence
    print(wn.synsets(word)[0].examples())
IndexError: list index out of range
500 Internal Server Error: The server encountered an internal error and was unable to complete your request. Either the server is overloaded or there is an error in the application.
Exception on /api/get_sentence [GET]
Traceback (most recent call last):
  File "D:\python\Python38\lib\site-packages\flask\app.py", line 2447, in wsgi_app
    response = self.full_dispatch_request()
  File "D:\python\Python38\lib\site-packages\flask\app.py", line 1952, in full_dispatch_request
    rv = self.handle_user_exception(e)
  File "D:\python\Python38\lib\site-packages\flask\app.py", line 1821, in handle_user_exception
    reraise(exc_type, exc_value, tb)
  File "D:\python\Python38\lib\site-packages\flask\_compat.py", line 39, in reraise
    raise value
  File "D:\python\Python38\lib\site-packages\flask\app.py", line 1950, in full_dispatch_request
    rv = self.dispatch_request()
  File "D:\python\Python38\lib\site-packages\flask\app.py", line 1936, in dispatch_request
    return self.view_functions[rule.endpoint](**req.view_args)
  File "app.py", line 58, in word_present_sentence
    word_for_sentence = print_sentence(word_sentence)
  File "app.py", line 28, in print_sentence
    print(wn.synsets(word)[0].examples())
IndexError: list index out of range
500 Internal Server Error: The server encountered an internal error and was unable to complete your request. Either the server is overloaded or there is an error in the application.
Exception on /api/get_sentence [GET]
Traceback (most recent call last):
  File "D:\python\Python38\lib\site-packages\flask\app.py", line 2447, in wsgi_app
    response = self.full_dispatch_request()
  File "D:\python\Python38\lib\site-packages\flask\app.py", line 1952, in full_dispatch_request
    rv = self.handle_user_exception(e)
  File "D:\python\Python38\lib\site-packages\flask\app.py", line 1821, in handle_user_exception
    reraise(exc_type, exc_value, tb)
  File "D:\python\Python38\lib\site-packages\flask\_compat.py", line 39, in reraise
    raise value
  File "D:\python\Python38\lib\site-packages\flask\app.py", line 1950, in full_dispatch_request
    rv = self.dispatch_request()
  File "D:\python\Python38\lib\site-packages\flask\app.py", line 1936, in dispatch_request
    return self.view_functions[rule.endpoint](**req.view_args)
  File "app.py", line 58, in word_present_sentence
    word_for_sentence = print_sentence(word_sentence)
  File "app.py", line 28, in print_sentence
    print(wn.synsets(word)[0].examples())
IndexError: list index out of range
500 Internal Server Error: The server encountered an internal error and was unable to complete your request. Either the server is overloaded or there is an error in the application.
Exception on /api/get_sentence [GET]
Traceback (most recent call last):
  File "D:\python\Python38\lib\site-packages\flask\app.py", line 2447, in wsgi_app
    response = self.full_dispatch_request()
  File "D:\python\Python38\lib\site-packages\flask\app.py", line 1952, in full_dispatch_request
    rv = self.handle_user_exception(e)
  File "D:\python\Python38\lib\site-packages\flask\app.py", line 1821, in handle_user_exception
    reraise(exc_type, exc_value, tb)
  File "D:\python\Python38\lib\site-packages\flask\_compat.py", line 39, in reraise
    raise value
  File "D:\python\Python38\lib\site-packages\flask\app.py", line 1950, in full_dispatch_request
    rv = self.dispatch_request()
  File "D:\python\Python38\lib\site-packages\flask\app.py", line 1936, in dispatch_request
    return self.view_functions[rule.endpoint](**req.view_args)
  File "app.py", line 58, in word_present_sentence
    word_for_sentence = print_sentence(word_sentence)
  File "app.py", line 28, in print_sentence
    print(wn.synsets(word)[0].examples())
  File "D:\python\Python38\lib\site-packages\nltk\corpus\util.py", line 99, in __getattr__
    self.__load()
  File "D:\python\Python38\lib\site-packages\nltk\corpus\util.py", line 73, in __load
    args, kwargs  = self.__args, self.__kwargs
AttributeError: 'WordNetCorpusReader' object has no attribute '_LazyCorpusLoader__args'
500 Internal Server Error: The server encountered an internal error and was unable to complete your request. Either the server is overloaded or there is an error in the application.
Exception on /api/get_sentence [GET]
Traceback (most recent call last):
  File "D:\python\Python38\lib\site-packages\flask\app.py", line 2447, in wsgi_app
    response = self.full_dispatch_request()
  File "D:\python\Python38\lib\site-packages\flask\app.py", line 1952, in full_dispatch_request
    rv = self.handle_user_exception(e)
  File "D:\python\Python38\lib\site-packages\flask\app.py", line 1821, in handle_user_exception
    reraise(exc_type, exc_value, tb)
  File "D:\python\Python38\lib\site-packages\flask\_compat.py", line 39, in reraise
    raise value
  File "D:\python\Python38\lib\site-packages\flask\app.py", line 1950, in full_dispatch_request
    rv = self.dispatch_request()
  File "D:\python\Python38\lib\site-packages\flask\app.py", line 1936, in dispatch_request
    return self.view_functions[rule.endpoint](**req.view_args)
  File "app.py", line 58, in word_present_sentence
    word_for_sentence = print_sentence(word_sentence)
  File "app.py", line 28, in print_sentence
    print(wn.synsets(word)[0].examples())
  File "D:\python\Python38\lib\site-packages\nltk\corpus\util.py", line 99, in __getattr__
    self.__load()
  File "D:\python\Python38\lib\site-packages\nltk\corpus\util.py", line 73, in __load
    args, kwargs  = self.__args, self.__kwargs
AttributeError: 'WordNetCorpusReader' object has no attribute '_LazyCorpusLoader__args'
500 Internal Server Error: The server encountered an internal error and was unable to complete your request. Either the server is overloaded or there is an error in the application.
Exception on /api/get_sentence [GET]
Traceback (most recent call last):
  File "D:\python\Python38\lib\site-packages\flask\app.py", line 2447, in wsgi_app
    response = self.full_dispatch_request()
  File "D:\python\Python38\lib\site-packages\flask\app.py", line 1952, in full_dispatch_request
    rv = self.handle_user_exception(e)
  File "D:\python\Python38\lib\site-packages\flask\app.py", line 1821, in handle_user_exception
    reraise(exc_type, exc_value, tb)
  File "D:\python\Python38\lib\site-packages\flask\_compat.py", line 39, in reraise
    raise value
  File "D:\python\Python38\lib\site-packages\flask\app.py", line 1950, in full_dispatch_request
    rv = self.dispatch_request()
  File "D:\python\Python38\lib\site-packages\flask\app.py", line 1936, in dispatch_request
    return self.view_functions[rule.endpoint](**req.view_args)
  File "app.py", line 58, in word_present_sentence
    word_for_sentence = print_sentence(word_sentence)
  File "app.py", line 28, in print_sentence
    print(wn.synsets(word)[0].examples())
  File "D:\python\Python38\lib\site-packages\nltk\corpus\util.py", line 99, in __getattr__
    self.__load()
  File "D:\python\Python38\lib\site-packages\nltk\corpus\util.py", line 73, in __load
    args, kwargs  = self.__args, self.__kwargs
AttributeError: 'WordNetCorpusReader' object has no attribute '_LazyCorpusLoader__args'
500 Internal Server Error: The server encountered an internal error and was unable to complete your request. Either the server is overloaded or there is an error in the application.
404 Not Found: The requested URL was not found on the server. If you entered the URL manually please check your spelling and try again.
404 Not Found: The requested URL was not found on the server. If you entered the URL manually please check your spelling and try again.
Exception on /api/get_sentence [GET]
Traceback (most recent call last):
  File "D:\python\Python38\lib\site-packages\flask\app.py", line 2447, in wsgi_app
    response = self.full_dispatch_request()
  File "D:\python\Python38\lib\site-packages\flask\app.py", line 1952, in full_dispatch_request
    rv = self.handle_user_exception(e)
  File "D:\python\Python38\lib\site-packages\flask\app.py", line 1821, in handle_user_exception
    reraise(exc_type, exc_value, tb)
  File "D:\python\Python38\lib\site-packages\flask\_compat.py", line 39, in reraise
    raise value
  File "D:\python\Python38\lib\site-packages\flask\app.py", line 1950, in full_dispatch_request
    rv = self.dispatch_request()
  File "D:\python\Python38\lib\site-packages\flask\app.py", line 1936, in dispatch_request
    return self.view_functions[rule.endpoint](**req.view_args)
  File "app.py", line 57, in word_present_sentence
    word_for_sentence = print_sentence(word_sentence)
  File "app.py", line 29, in print_sentence
    return (wn.synsets(word)[0].examples(items))
NameError: name 'items' is not defined
500 Internal Server Error: The server encountered an internal error and was unable to complete your request. Either the server is overloaded or there is an error in the application.
404 Not Found: The requested URL was not found on the server. If you entered the URL manually please check your spelling and try again.
Exception on /api/get_sentence [GET]
Traceback (most recent call last):
  File "D:\python\Python38\lib\site-packages\flask\app.py", line 2447, in wsgi_app
    response = self.full_dispatch_request()
  File "D:\python\Python38\lib\site-packages\flask\app.py", line 1952, in full_dispatch_request
    rv = self.handle_user_exception(e)
  File "D:\python\Python38\lib\site-packages\flask\app.py", line 1821, in handle_user_exception
    reraise(exc_type, exc_value, tb)
  File "D:\python\Python38\lib\site-packages\flask\_compat.py", line 39, in reraise
    raise value
  File "D:\python\Python38\lib\site-packages\flask\app.py", line 1950, in full_dispatch_request
    rv = self.dispatch_request()
  File "D:\python\Python38\lib\site-packages\flask\app.py", line 1936, in dispatch_request
    return self.view_functions[rule.endpoint](**req.view_args)
  File "app.py", line 57, in word_present_sentence
    word_for_sentence = print_sentence(word_sentence)
  File "app.py", line 29, in print_sentence
    return (wn.synsets(word)[0].examples(item))
TypeError: examples() takes 1 positional argument but 2 were given
500 Internal Server Error: The server encountered an internal error and was unable to complete your request. Either the server is overloaded or there is an error in the application.
Exception on /api/get_sentence [GET]
Traceback (most recent call last):
  File "D:\python\Python38\lib\site-packages\flask\app.py", line 2447, in wsgi_app
    response = self.full_dispatch_request()
  File "D:\python\Python38\lib\site-packages\flask\app.py", line 1952, in full_dispatch_request
    rv = self.handle_user_exception(e)
  File "D:\python\Python38\lib\site-packages\flask\app.py", line 1821, in handle_user_exception
    reraise(exc_type, exc_value, tb)
  File "D:\python\Python38\lib\site-packages\flask\_compat.py", line 39, in reraise
    raise value
  File "D:\python\Python38\lib\site-packages\flask\app.py", line 1950, in full_dispatch_request
    rv = self.dispatch_request()
  File "D:\python\Python38\lib\site-packages\flask\app.py", line 1936, in dispatch_request
    return self.view_functions[rule.endpoint](**req.view_args)
  File "app.py", line 57, in word_present_sentence
    word_for_sentence = print_sentence(word_sentence)
  File "app.py", line 29, in print_sentence
    return (wn.synsets(word)[0].examples(item))
TypeError: examples() takes 1 positional argument but 2 were given
500 Internal Server Error: The server encountered an internal error and was unable to complete your request. Either the server is overloaded or there is an error in the application.
404 Not Found: The requested URL was not found on the server. If you entered the URL manually please check your spelling and try again.
Exception on /api/get_sentence [GET]
Traceback (most recent call last):
  File "D:\python\Python38\lib\site-packages\flask\app.py", line 2447, in wsgi_app
    response = self.full_dispatch_request()
  File "D:\python\Python38\lib\site-packages\flask\app.py", line 1952, in full_dispatch_request
    rv = self.handle_user_exception(e)
  File "D:\python\Python38\lib\site-packages\flask\app.py", line 1821, in handle_user_exception
    reraise(exc_type, exc_value, tb)
  File "D:\python\Python38\lib\site-packages\flask\_compat.py", line 39, in reraise
    raise value
  File "D:\python\Python38\lib\site-packages\flask\app.py", line 1950, in full_dispatch_request
    rv = self.dispatch_request()
  File "D:\python\Python38\lib\site-packages\flask\app.py", line 1936, in dispatch_request
    return self.view_functions[rule.endpoint](**req.view_args)
  File "app.py", line 58, in word_present_sentence
    return jsonify(word_for_sentence)
  File "D:\python\Python38\lib\site-packages\flask\json\__init__.py", line 370, in jsonify
    dumps(data, indent=indent, separators=separators) + "\n",
  File "D:\python\Python38\lib\site-packages\flask\json\__init__.py", line 211, in dumps
    rv = _json.dumps(obj, **kwargs)
  File "D:\python\Python38\lib\json\__init__.py", line 234, in dumps
    return cls(
  File "D:\python\Python38\lib\json\encoder.py", line 199, in encode
    chunks = self.iterencode(o, _one_shot=True)
  File "D:\python\Python38\lib\json\encoder.py", line 257, in iterencode
    return _iterencode(o, 0)
  File "D:\python\Python38\lib\site-packages\flask\json\__init__.py", line 100, in default
    return _json.JSONEncoder.default(self, o)
  File "D:\python\Python38\lib\json\encoder.py", line 179, in default
    raise TypeError(f'Object of type {o.__class__.__name__} '
TypeError: Object of type method is not JSON serializable
500 Internal Server Error: The server encountered an internal error and was unable to complete your request. Either the server is overloaded or there is an error in the application.
Exception on /api/get_sentence [GET]
Traceback (most recent call last):
  File "D:\python\Python38\lib\site-packages\flask\app.py", line 2447, in wsgi_app
    response = self.full_dispatch_request()
  File "D:\python\Python38\lib\site-packages\flask\app.py", line 1952, in full_dispatch_request
    rv = self.handle_user_exception(e)
  File "D:\python\Python38\lib\site-packages\flask\app.py", line 1821, in handle_user_exception
    reraise(exc_type, exc_value, tb)
  File "D:\python\Python38\lib\site-packages\flask\_compat.py", line 39, in reraise
    raise value
  File "D:\python\Python38\lib\site-packages\flask\app.py", line 1950, in full_dispatch_request
    rv = self.dispatch_request()
  File "D:\python\Python38\lib\site-packages\flask\app.py", line 1936, in dispatch_request
    return self.view_functions[rule.endpoint](**req.view_args)
  File "app.py", line 58, in word_present_sentence
    return jsonify(word_for_sentence)
  File "D:\python\Python38\lib\site-packages\flask\json\__init__.py", line 370, in jsonify
    dumps(data, indent=indent, separators=separators) + "\n",
  File "D:\python\Python38\lib\site-packages\flask\json\__init__.py", line 211, in dumps
    rv = _json.dumps(obj, **kwargs)
  File "D:\python\Python38\lib\json\__init__.py", line 234, in dumps
    return cls(
  File "D:\python\Python38\lib\json\encoder.py", line 199, in encode
    chunks = self.iterencode(o, _one_shot=True)
  File "D:\python\Python38\lib\json\encoder.py", line 257, in iterencode
    return _iterencode(o, 0)
  File "D:\python\Python38\lib\site-packages\flask\json\__init__.py", line 100, in default
    return _json.JSONEncoder.default(self, o)
  File "D:\python\Python38\lib\json\encoder.py", line 179, in default
    raise TypeError(f'Object of type {o.__class__.__name__} '
TypeError: Object of type method is not JSON serializable
500 Internal Server Error: The server encountered an internal error and was unable to complete your request. Either the server is overloaded or there is an error in the application.
404 Not Found: The requested URL was not found on the server. If you entered the URL manually please check your spelling and try again.
Exception on /api/get_sentence [GET]
Traceback (most recent call last):
  File "D:\python\Python38\lib\site-packages\flask\app.py", line 2447, in wsgi_app
    response = self.full_dispatch_request()
  File "D:\python\Python38\lib\site-packages\flask\app.py", line 1952, in full_dispatch_request
    rv = self.handle_user_exception(e)
  File "D:\python\Python38\lib\site-packages\flask\app.py", line 1821, in handle_user_exception
    reraise(exc_type, exc_value, tb)
  File "D:\python\Python38\lib\site-packages\flask\_compat.py", line 39, in reraise
    raise value
  File "D:\python\Python38\lib\site-packages\flask\app.py", line 1950, in full_dispatch_request
    rv = self.dispatch_request()
  File "D:\python\Python38\lib\site-packages\flask\app.py", line 1936, in dispatch_request
    return self.view_functions[rule.endpoint](**req.view_args)
  File "app.py", line 58, in word_present_sentence
    return jsonify(word_for_sentence)
  File "D:\python\Python38\lib\site-packages\flask\json\__init__.py", line 370, in jsonify
    dumps(data, indent=indent, separators=separators) + "\n",
  File "D:\python\Python38\lib\site-packages\flask\json\__init__.py", line 211, in dumps
    rv = _json.dumps(obj, **kwargs)
  File "D:\python\Python38\lib\json\__init__.py", line 234, in dumps
    return cls(
  File "D:\python\Python38\lib\json\encoder.py", line 199, in encode
    chunks = self.iterencode(o, _one_shot=True)
  File "D:\python\Python38\lib\json\encoder.py", line 257, in iterencode
    return _iterencode(o, 0)
  File "D:\python\Python38\lib\site-packages\flask\json\__init__.py", line 100, in default
    return _json.JSONEncoder.default(self, o)
  File "D:\python\Python38\lib\json\encoder.py", line 179, in default
    raise TypeError(f'Object of type {o.__class__.__name__} '
TypeError: Object of type method is not JSON serializable
500 Internal Server Error: The server encountered an internal error and was unable to complete your request. Either the server is overloaded or there is an error in the application.
Exception on /api/get_sentence [GET]
Traceback (most recent call last):
  File "D:\python\Python38\lib\site-packages\flask\app.py", line 2447, in wsgi_app
    response = self.full_dispatch_request()
  File "D:\python\Python38\lib\site-packages\flask\app.py", line 1952, in full_dispatch_request
    rv = self.handle_user_exception(e)
  File "D:\python\Python38\lib\site-packages\flask\app.py", line 1821, in handle_user_exception
    reraise(exc_type, exc_value, tb)
  File "D:\python\Python38\lib\site-packages\flask\_compat.py", line 39, in reraise
    raise value
  File "D:\python\Python38\lib\site-packages\flask\app.py", line 1950, in full_dispatch_request
    rv = self.dispatch_request()
  File "D:\python\Python38\lib\site-packages\flask\app.py", line 1936, in dispatch_request
    return self.view_functions[rule.endpoint](**req.view_args)
  File "app.py", line 58, in word_present_sentence
    return jsonify(word_for_sentence)
  File "D:\python\Python38\lib\site-packages\flask\json\__init__.py", line 370, in jsonify
    dumps(data, indent=indent, separators=separators) + "\n",
  File "D:\python\Python38\lib\site-packages\flask\json\__init__.py", line 211, in dumps
    rv = _json.dumps(obj, **kwargs)
  File "D:\python\Python38\lib\json\__init__.py", line 234, in dumps
    return cls(
  File "D:\python\Python38\lib\json\encoder.py", line 199, in encode
    chunks = self.iterencode(o, _one_shot=True)
  File "D:\python\Python38\lib\json\encoder.py", line 257, in iterencode
    return _iterencode(o, 0)
  File "D:\python\Python38\lib\site-packages\flask\json\__init__.py", line 100, in default
    return _json.JSONEncoder.default(self, o)
  File "D:\python\Python38\lib\json\encoder.py", line 179, in default
    raise TypeError(f'Object of type {o.__class__.__name__} '
TypeError: Object of type method is not JSON serializable
500 Internal Server Error: The server encountered an internal error and was unable to complete your request. Either the server is overloaded or there is an error in the application.
Exception on /api/get_sentence [GET]
Traceback (most recent call last):
  File "D:\python\Python38\lib\site-packages\flask\app.py", line 2447, in wsgi_app
    response = self.full_dispatch_request()
  File "D:\python\Python38\lib\site-packages\flask\app.py", line 1952, in full_dispatch_request
    rv = self.handle_user_exception(e)
  File "D:\python\Python38\lib\site-packages\flask\app.py", line 1821, in handle_user_exception
    reraise(exc_type, exc_value, tb)
  File "D:\python\Python38\lib\site-packages\flask\_compat.py", line 39, in reraise
    raise value
  File "D:\python\Python38\lib\site-packages\flask\app.py", line 1950, in full_dispatch_request
    rv = self.dispatch_request()
  File "D:\python\Python38\lib\site-packages\flask\app.py", line 1936, in dispatch_request
    return self.view_functions[rule.endpoint](**req.view_args)
  File "app.py", line 58, in word_present_sentence
    return jsonify(word_for_sentence)
  File "D:\python\Python38\lib\site-packages\flask\json\__init__.py", line 370, in jsonify
    dumps(data, indent=indent, separators=separators) + "\n",
  File "D:\python\Python38\lib\site-packages\flask\json\__init__.py", line 211, in dumps
    rv = _json.dumps(obj, **kwargs)
  File "D:\python\Python38\lib\json\__init__.py", line 234, in dumps
    return cls(
  File "D:\python\Python38\lib\json\encoder.py", line 199, in encode
    chunks = self.iterencode(o, _one_shot=True)
  File "D:\python\Python38\lib\json\encoder.py", line 257, in iterencode
    return _iterencode(o, 0)
  File "D:\python\Python38\lib\site-packages\flask\json\__init__.py", line 100, in default
    return _json.JSONEncoder.default(self, o)
  File "D:\python\Python38\lib\json\encoder.py", line 179, in default
    raise TypeError(f'Object of type {o.__class__.__name__} '
TypeError: Object of type method is not JSON serializable
500 Internal Server Error: The server encountered an internal error and was unable to complete your request. Either the server is overloaded or there is an error in the application.
404 Not Found: The requested URL was not found on the server. If you entered the URL manually please check your spelling and try again.
404 Not Found: The requested URL was not found on the server. If you entered the URL manually please check your spelling and try again.
404 Not Found: The requested URL was not found on the server. If you entered the URL manually please check your spelling and try again.
404 Not Found: The requested URL was not found on the server. If you entered the URL manually please check your spelling and try again.
404 Not Found: The requested URL was not found on the server. If you entered the URL manually please check your spelling and try again.
404 Not Found: The requested URL was not found on the server. If you entered the URL manually please check your spelling and try again.
404 Not Found: The requested URL was not found on the server. If you entered the URL manually please check your spelling and try again.
404 Not Found: The requested URL was not found on the server. If you entered the URL manually please check your spelling and try again.
404 Not Found: The requested URL was not found on the server. If you entered the URL manually please check your spelling and try again.
Exception on /api/get_sentence [GET]
Traceback (most recent call last):
  File "D:\python\Python38\lib\site-packages\flask\app.py", line 2447, in wsgi_app
    response = self.full_dispatch_request()
  File "D:\python\Python38\lib\site-packages\flask\app.py", line 1952, in full_dispatch_request
    rv = self.handle_user_exception(e)
  File "D:\python\Python38\lib\site-packages\flask\app.py", line 1821, in handle_user_exception
    reraise(exc_type, exc_value, tb)
  File "D:\python\Python38\lib\site-packages\flask\_compat.py", line 39, in reraise
    raise value
  File "D:\python\Python38\lib\site-packages\flask\app.py", line 1950, in full_dispatch_request
    rv = self.dispatch_request()
  File "D:\python\Python38\lib\site-packages\flask\app.py", line 1936, in dispatch_request
    return self.view_functions[rule.endpoint](**req.view_args)
  File "app.py", line 60, in word_present_sentence
    word_for_sentence = print_sentence(word_sentence)
  File "app.py", line 29, in print_sentence
    return (wn.synsets(word)[0].examples())
  File "D:\python\Python38\lib\site-packages\nltk\corpus\util.py", line 99, in __getattr__
    self.__load()
  File "D:\python\Python38\lib\site-packages\nltk\corpus\util.py", line 73, in __load
    args, kwargs  = self.__args, self.__kwargs
AttributeError: 'WordNetCorpusReader' object has no attribute '_LazyCorpusLoader__args'
500 Internal Server Error: The server encountered an internal error and was unable to complete your request. Either the server is overloaded or there is an error in the application.
404 Not Found: The requested URL was not found on the server. If you entered the URL manually please check your spelling and try again.
404 Not Found: The requested URL was not found on the server. If you entered the URL manually please check your spelling and try again.
404 Not Found: The requested URL was not found on the server. If you entered the URL manually please check your spelling and try again.
404 Not Found: The requested URL was not found on the server. If you entered the URL manually please check your spelling and try again.
404 Not Found: The requested URL was not found on the server. If you entered the URL manually please check your spelling and try again.
404 Not Found: The requested URL was not found on the server. If you entered the URL manually please check your spelling and try again.
Exception on /api/get_sentence [GET]
Traceback (most recent call last):
  File "D:\python\Python38\lib\site-packages\flask\app.py", line 2447, in wsgi_app
    response = self.full_dispatch_request()
  File "D:\python\Python38\lib\site-packages\flask\app.py", line 1952, in full_dispatch_request
    rv = self.handle_user_exception(e)
  File "D:\python\Python38\lib\site-packages\flask\app.py", line 1821, in handle_user_exception
    reraise(exc_type, exc_value, tb)
  File "D:\python\Python38\lib\site-packages\flask\_compat.py", line 39, in reraise
    raise value
  File "D:\python\Python38\lib\site-packages\flask\app.py", line 1950, in full_dispatch_request
    rv = self.dispatch_request()
  File "D:\python\Python38\lib\site-packages\flask\app.py", line 1936, in dispatch_request
    return self.view_functions[rule.endpoint](**req.view_args)
  File "app.py", line 55, in word_present_sentence
    word_for_sentence = print_sentence(word_sentence)
  File "app.py", line 27, in print_sentence
    return (wn.synsets(word)[0].examples())
  File "D:\python\Python38\lib\site-packages\nltk\corpus\util.py", line 99, in __getattr__
    self.__load()
  File "D:\python\Python38\lib\site-packages\nltk\corpus\util.py", line 73, in __load
    args, kwargs  = self.__args, self.__kwargs
AttributeError: 'WordNetCorpusReader' object has no attribute '_LazyCorpusLoader__args'
500 Internal Server Error: The server encountered an internal error and was unable to complete your request. Either the server is overloaded or there is an error in the application.
404 Not Found: The requested URL was not found on the server. If you entered the URL manually please check your spelling and try again.
404 Not Found: The requested URL was not found on the server. If you entered the URL manually please check your spelling and try again.
404 Not Found: The requested URL was not found on the server. If you entered the URL manually please check your spelling and try again.
